Workbook

Sheet  01-03-26
C2: VARIABLE DE CONTROL SISTEMA DE GENERACIÓN DE VAPOR " PLANTA SALSAS Y UNTABLES" | H2: Codigo: FOXXX-0704-MAN
H3: Fecha actualización: XX/XX/XXXX
H4: Versión: X
A6: NOMBRE DE LA PLANTA: Alimentos Polar Comercial, C.A. Salsas y Untables
A7: DIRECCIÓN: Avenida Luis Ernesto Branger, Zona Industrial Norte II, Parroquia Rafael Urdaneta, Valencia, Edo. Carabobo,
A8: Venezuela. Código postal 2001.
A11: FECHA: | B11: 46082 | C11: Nombre y Apellido | E11: Eliezer D | F11: Angel M | G11: Observaciones
A12: Area | B12: Variable de control | D12: Rango Operación | E12: 1er Turno | F12: 2do Turno
E13: 0.29166667 | F13: 0.79166667
A14: Alimentación Calderas | B14: Hierro Total | C14: Semanal | D14: ≤ 0,1 mg/l
B15: Temperatura | C15: Diaria | D15: ≥ 104 °C | E15: 93.4 | F15: 98.5
B16: Dureza Total en CaCO3 | C16: Diaria | D16: ≤ 0,3 mg/l
B17: Conductividad | C17: Semanal | D17: −
B18: pH | C18: Diaria | D18: 8,5 - 10,0 | E18: 7.69 | F18: 7.68
B19: Sílice en SiO2 | C19: Semanal | D19: −
B20: Alcalinidad +M en CaCO3 | C20: Semanal | D20: −
B21: Alcalinidad OH¯ en CaCO3 | C21: Semanal | D21: −
A23: Caldera N°1 | B23: Alcalinidad +M en CaCO3 | C23: Semanal | D23: ≤ 700 mg/l
B24: Alcalinidad OH¯ en CaCO3 | C24: Semanal | D24: ≥ 40 mg/l
B25: Conductividad | C25: Diaria | D25: 1.100 - 1.500 uS/cm | E25: 2985
B26: pH | C26: Diaria | D26: 10,5 - 11,9 | E26: 11.6 | F26: 11.54
B27: Sílice en SiO2 | C27: Semanal | D27: ≤ 150 mg/l
B28: Dureza Total en CaCO3 | C28: Semanal | D28: ˂ 3 mg/l
B29: Hierro Total | C29: Mensual | D29: ˂ 1 mg/l
B30: Sulfito | C30: Diaria | D30: 30 - 60 mg/l | E30: 50 | F30: 45
B31: Fosfato | C31: Diaria | D31: 30 - 60 mg/l | E31: 45 | F31: 40
B32: TDS | C32: Diaria | D32: − | E32: 2171 | F32: 2670
A34: Caldera N°2 | B34: Alcalinidad +M en CaCO3 | C34: Semanal | D34: ≤ 700 mg/l
B35: Alcalinidad OH¯ en CaCO3 | C35: Semanal | D35: ≥ 40 mg/l
B36: Conductividad | C36: Diaria | D36: 1.100 - 1.500 uS/cm | E36: 2468
B37: pH | C37: Diaria | D37: 10,5 - 11,9 | E37: 11.59 | F37: 11.67
B38: Sílice en SiO2 | C38: Semanal | D38: ≤ 150 mg/l
B39: Dureza Total en CaCO3 | C39: Semanal | D39: ˂ 3 mg/l
B40: Hierro Total | C40: Mensual | D40: ˂ 1 mg/l
B41: Sulfito | C41: Diaria | D41: 30 - 60 mg/l | E41: 35 | F41: 30
B42: Fosfato | C42: Diaria | D42: 30 - 60 mg/l | E42: 30 | F42: 30
B43: TDS | C43: Diaria | D43: − | E43: 1770 | F43: 1890
A45: Caldera N°3 | B45: Alcalinidad +M en CaCO3 | C45: Semanal | D45: ≤ 700 mg/l
B46: Alcalinidad OH¯ en CaCO3 | C46: Semanal | D46: ≥ 40 mg/l
B47: Conductividad | C47: Diaria | D47: 1.100 - 1.500 uS/cm
...

Sheet  02-03-26
C2: VARIABLE DE CONTROL SISTEMA DE GENERACIÓN DE VAPOR " PLANTA SALSAS Y UNTABLES" | H2: Codigo: FOXXX-0704-MAN
H3: Fecha actualización: XX/XX/XXXX
H4: Versión: X
A6: NOMBRE DE LA PLANTA: Alimentos Polar Comercial, C.A. Salsas y Untables
A7: DIRECCIÓN: Avenida Luis Ernesto Branger, Zona Industrial Norte II, Parroquia Rafael Urdaneta, Valencia, Edo. Carabobo,
A8: Venezuela. Código postal 2001.
A11: FECHA: | B11: 46083 | C11: Nombre y Apellido | E11: Osman A | F11: Eliezer D | G11: Observaciones
A12: Area | B12: Variable de control | D12: Rango Operación | E12: 1er Turno | F12: 2do Turno
E13: 0.29166667 | F13: 0.79166667
A14: Alimentación Calderas | B14: Hierro Total | C14: Semanal | D14: ≤ 0,1 mg/l
B15: Temperatura | C15: Diaria | D15: ≥ 104 °C | E15: 91.4 | F15: 93.1
B16: Dureza Total en CaCO3 | C16: Diaria | D16: ≤ 0,3 mg/l
B17: Conductividad | C17: Semanal | D17: − | E17: 673
B18: pH | C18: Diaria | D18: 8,5 - 10,0 | E18: 7.96 | F18: 7.63
B19: Sílice en SiO2 | C19: Semanal | D19: −
B20: Alcalinidad +M en CaCO3 | C20: Semanal | D20: −
B21: Alcalinidad OH¯ en CaCO3 | C21: Semanal | D21: −
A23: Caldera N°1 | B23: Alcalinidad +M en CaCO3 | C23: Semanal | D23: ≤ 700 mg/l | E23: 872
B24: Alcalinidad OH¯ en CaCO3 | C24: Semanal | D24: ≥ 40 mg/l | E24: 488
B25: Conductividad | C25: Diaria | D25: 1.100 - 1.500 uS/cm | E25: 3000 | F25: 2432
B26: pH | C26: Diaria | D26: 10,5 - 11,9 | E26: 11.74 | F26: 11.71
B27: Sílice en SiO2 | C27: Semanal | D27: ≤ 150 mg/l
B28: Dureza Total en CaCO3 | C28: Semanal | D28: ˂ 3 mg/l
B29: Hierro Total | C29: Mensual | D29: ˂ 1 mg/l
B30: Sulfito | C30: Diaria | D30: 30 - 60 mg/l | E30: 70 | F30: 55
B31: Fosfato | C31: Diaria | D31: 30 - 60 mg/l | E31: 30 | F31: 35
B32: TDS | C32: Diaria | D32: − | E32: 2182 | F32: 2310
A34: Caldera N°2 | B34: Alcalinidad +M en CaCO3 | C34: Semanal | D34: ≤ 700 mg/l | E34: 700
B35: Alcalinidad OH¯ en CaCO3 | C35: Semanal | D35: ≥ 40 mg/l | E35: 356
B36: Conductividad | C36: Diaria | D36: 1.100 - 1.500 uS/cm | E36: 2416 | F36: 2523
B37: pH | C37: Diaria | D37: 10,5 - 11,9 | E37: 11.68 | F37: 11.61
B38: Sílice en SiO2 | C38: Semanal | D38: ≤ 150 mg/l
B39: Dureza Total en CaCO3 | C39: Semanal | D39: ˂ 3 mg/l
B40: Hierro Total | C40: Mensual | D40: ˂ 1 mg/l
B41: Sulfito | C41: Diaria | D41: 30 - 60 mg/l | E41: 39 | F41: 42
B42: Fosfato | C42: Diaria | D42: 30 - 60 mg/l | E42: 30 | F42: 32.5
B43: TDS | C43: Diaria | D43: − | E43: 1760 | F43: 1832
A45: Caldera N°3 | B45: Alcalinidad +M en CaCO3 | C45: Semanal | D45: ≤ 700 mg/l | E45: 440
B46: Alcalinidad OH¯ en CaCO3 | C46: Semanal | D46: ≥ 40 mg/l | E46: 216
B47: Conductividad | C47: Diaria | D47: 1.100 - 1.500 uS/cm | E47: 1561
...

Sheet  03-03-26
C2: VARIABLE DE CONTROL SISTEMA DE GENERACIÓN DE VAPOR " PLANTA SALSAS Y UNTABLES" | H2: Codigo: FOXXX-0704-MAN
H3: Fecha actualización: XX/XX/XXXX
H4: Versión: X
A6: NOMBRE DE LA PLANTA: Alimentos Polar Comercial, C.A. Salsas y Untables
A7: DIRECCIÓN: Avenida Luis Ernesto Branger, Zona Industrial Norte II, Parroquia Rafael Urdaneta, Valencia, Edo. Carabobo,
A8: Venezuela. Código postal 2001.
A11: FECHA: | B11: 46084 | C11: Nombre y Apellido | E11: Osman A | F11: Eliezer D | G11: Observaciones
A12: Area | B12: Variable de control | D12: Rango Operación | E12: 1er Turno | F12: 2do Turno
E13: 0.29166667 | F13: 0.79166667
A14: Alimentación Calderas | B14: Hierro Total | C14: Semanal | D14: ≤ 0,1 mg/l | E14: 0.39
B15: Temperatura | C15: Diaria | D15: ≥ 104 °C | E15: 92.2 | F15: 91.2
B16: Dureza Total en CaCO3 | C16: Diaria | D16: ≤ 0,3 mg/l | E16: 2.54
B17: Conductividad | C17: Semanal | D17: − | E17: 598
B18: pH | C18: Diaria | D18: 8,5 - 10,0 | E18: 7.68 | F18: 7.62
B19: Sílice en SiO2 | C19: Semanal | D19: − | E19: 37
B20: Alcalinidad +M en CaCO3 | C20: Semanal | D20: − | E20: 268
B21: Alcalinidad OH¯ en CaCO3 | C21: Semanal | D21: −
A23: Caldera N°1 | B23: Alcalinidad +M en CaCO3 | C23: Semanal | D23: ≤ 700 mg/l | E23: 816
B24: Alcalinidad OH¯ en CaCO3 | C24: Semanal | D24: ≥ 40 mg/l | E24: 440
B25: Conductividad | C25: Diaria | D25: 1.100 - 1.500 uS/cm | E25: 2560 | F25: 3812
B26: pH | C26: Diaria | D26: 10,5 - 11,9 | E26: 10.66 | F26: 11.89
B27: Sílice en SiO2 | C27: Semanal | D27: ≤ 150 mg/l | E27: 92.5
B28: Dureza Total en CaCO3 | C28: Semanal | D28: ˂ 3 mg/l | E28: 2.71
B29: Hierro Total | C29: Mensual | D29: ˂ 1 mg/l | E29: 0.2
B30: Sulfito | C30: Diaria | D30: 30 - 60 mg/l | E30: 51 | F30: 58
B31: Fosfato | C31: Diaria | D31: 30 - 60 mg/l | E31: 37.5 | F31: 45
B32: TDS | C32: Diaria | D32: − | F32: 2888
A34: Caldera N°2 | B34: Alcalinidad +M en CaCO3 | C34: Semanal | D34: ≤ 700 mg/l | E34: 880
B35: Alcalinidad OH¯ en CaCO3 | C35: Semanal | D35: ≥ 40 mg/l | E35: 592
B36: Conductividad | C36: Diaria | D36: 1.100 - 1.500 uS/cm | E36: 2700 | F36: 3459
B37: pH | C37: Diaria | D37: 10,5 - 11,9 | E37: 10.89 | F37: 11.9
B38: Sílice en SiO2 | C38: Semanal | D38: ≤ 150 mg/l | E38: 115
B39: Dureza Total en CaCO3 | C39: Semanal | D39: ˂ 3 mg/l | E39: 1.06
B40: Hierro Total | C40: Mensual | D40: ˂ 1 mg/l | E40: 0.71
B41: Sulfito | C41: Diaria | D41: 30 - 60 mg/l | E41: 49 | F41: 46
B42: Fosfato | C42: Diaria | D42: 30 - 60 mg/l | E42: 42.5 | F42: 45
B43: TDS | C43: Diaria | D43: − | F43: 2556
A45: Caldera N°3 | B45: Alcalinidad +M en CaCO3 | C45: Semanal | D45: ≤ 700 mg/l | E45: 688
B46: Alcalinidad OH¯ en CaCO3 | C46: Semanal | D46: ≥ 40 mg/l | E46: 360
B47: Conductividad | C47: Diaria | D47: 1.100 - 1.500 uS/cm | E47: 1866 | F47: 2274
...

Sheet  04-03-26
C2: VARIABLE DE CONTROL SISTEMA DE GENERACIÓN DE VAPOR " PLANTA SALSAS Y UNTABLES" | H2: Codigo: FOXXX-0704-MAN
H3: Fecha actualización: XX/XX/XXXX
H4: Versión: X
A6: NOMBRE DE LA PLANTA: Alimentos Polar Comercial, C.A. Salsas y Untables
A7: DIRECCIÓN: Avenida Luis Ernesto Branger, Zona Industrial Norte II, Parroquia Rafael Urdaneta, Valencia, Edo. Carabobo,
A8: Venezuela. Código postal 2001.
A11: FECHA: | B11: 46085 | C11: Nombre y Apellido | E11: Arturo C | F11: Osman A | G11: Observaciones
A12: Area | B12: Variable de control | D12: Rango Operación | E12: 1er Turno | F12: 2do Turno
E13: 0.29166667 | F13: 0.79166667
A14: Alimentación Calderas | B14: Hierro Total | C14: Semanal | D14: ≤ 0,1 mg/l
B15: Temperatura | C15: Diaria | D15: ≥ 104 °C | E15: 91.6 | F15: 92.4
B16: Dureza Total en CaCO3 | C16: Diaria | D16: ≤ 0,3 mg/l
B17: Conductividad | C17: Semanal | D17: − | E17: 617 | F17: 632
B18: pH | C18: Diaria | D18: 8,5 - 10,0 | E18: 7.71 | F18: 7.84
B19: Sílice en SiO2 | C19: Semanal | D19: −
B20: Alcalinidad +M en CaCO3 | C20: Semanal | D20: −
B21: Alcalinidad OH¯ en CaCO3 | C21: Semanal | D21: −
A23: Caldera N°1 | B23: Alcalinidad +M en CaCO3 | C23: Semanal | D23: ≤ 700 mg/l
B24: Alcalinidad OH¯ en CaCO3 | C24: Semanal | D24: ≥ 40 mg/l
B25: Conductividad | C25: Diaria | D25: 1.100 - 1.500 uS/cm | E25: 3291 | F25: 3640
B26: pH | C26: Diaria | D26: 10,5 - 11,9 | E26: 11.93 | F26: 11.82
B27: Sílice en SiO2 | C27: Semanal | D27: ≤ 150 mg/l
B28: Dureza Total en CaCO3 | C28: Semanal | D28: ˂ 3 mg/l
B29: Hierro Total | C29: Mensual | D29: ˂ 1 mg/l
B30: Sulfito | C30: Diaria | D30: 30 - 60 mg/l | E30: 95 | F30: 64
B31: Fosfato | C31: Diaria | D31: 30 - 60 mg/l | E31: 60 | F31: 50
B32: TDS | C32: Diaria | D32: − | E32: 2922 | F32: 2715
A34: Caldera N°2 | B34: Alcalinidad +M en CaCO3 | C34: Semanal | D34: ≤ 700 mg/l
B35: Alcalinidad OH¯ en CaCO3 | C35: Semanal | D35: ≥ 40 mg/l
B36: Conductividad | C36: Diaria | D36: 1.100 - 1.500 uS/cm | E36: 3537 | F36: 3552
B37: pH | C37: Diaria | D37: 10,5 - 11,9 | E37: 11.84 | F37: 11.79
B38: Sílice en SiO2 | C38: Semanal | D38: ≤ 150 mg/l
B39: Dureza Total en CaCO3 | C39: Semanal | D39: ˂ 3 mg/l
B40: Hierro Total | C40: Mensual | D40: ˂ 1 mg/l
B41: Sulfito | C41: Diaria | D41: 30 - 60 mg/l | E41: 56 | F41: 47
B42: Fosfato | C42: Diaria | D42: 30 - 60 mg/l | E42: 40 | F42: 57.5
B43: TDS | C43: Diaria | D43: − | E43: 2605 | F43: 2470
A45: Caldera N°3 | B45: Alcalinidad +M en CaCO3 | C45: Semanal | D45: ≤ 700 mg/l
B46: Alcalinidad OH¯ en CaCO3 | C46: Semanal | D46: ≥ 40 mg/l
B47: Conductividad | C47: Diaria | D47: 1.100 - 1.500 uS/cm | E47: 1994 | F47: 1460
...

Sheet  05-03-26
C2: VARIABLE DE CONTROL SISTEMA DE GENERACIÓN DE VAPOR " PLANTA SALSAS Y UNTABLES" | H2: Codigo: FOXXX-0704-MAN
H3: Fecha actualización: XX/XX/XXXX
H4: Versión: X
A6: NOMBRE DE LA PLANTA: Alimentos Polar Comercial, C.A. Salsas y Untables
A7: DIRECCIÓN: Avenida Luis Ernesto Branger, Zona Industrial Norte II, Parroquia Rafael Urdaneta, Valencia, Edo. Carabobo,
A8: Venezuela. Código postal 2001.
A11: FECHA: | B11: 46086 | C11: Nombre y Apellido | E11: Arturo C | F11: Osman A | G11: Observaciones
A12: Area | B12: Variable de control | D12: Rango Operación | E12: 1er Turno | F12: 2do Turno
E13: 0.29166667 | F13: 0.79166667
A14: Alimentación Calderas | B14: Hierro Total | C14: Semanal | D14: ≤ 0,1 mg/l
B15: Temperatura | C15: Diaria | D15: ≥ 104 °C | E15: 93.8 | F15: 93.2
B16: Dureza Total en CaCO3 | C16: Diaria | D16: ≤ 0,3 mg/l
B17: Conductividad | C17: Semanal | D17: − | E17: 598 | F17: 610
B18: pH | C18: Diaria | D18: 8,5 - 10,0 | E18: 7.98 | F18: 7.84
B19: Sílice en SiO2 | C19: Semanal | D19: −
B20: Alcalinidad +M en CaCO3 | C20: Semanal | D20: −
B21: Alcalinidad OH¯ en CaCO3 | C21: Semanal | D21: −
A23: Caldera N°1 | B23: Alcalinidad +M en CaCO3 | C23: Semanal | D23: ≤ 700 mg/l
B24: Alcalinidad OH¯ en CaCO3 | C24: Semanal | D24: ≥ 40 mg/l
B25: Conductividad | C25: Diaria | D25: 1.100 - 1.500 uS/cm | E25: 3925 | F25: 3374
B26: pH | C26: Diaria | D26: 10,5 - 11,9 | E26: 11.93 | F26: 11.67
B27: Sílice en SiO2 | C27: Semanal | D27: ≤ 150 mg/l
B28: Dureza Total en CaCO3 | C28: Semanal | D28: ˂ 3 mg/l
B29: Hierro Total | C29: Mensual | D29: ˂ 1 mg/l
B30: Sulfito | C30: Diaria | D30: 30 - 60 mg/l | E30: 74 | F30: 70
B31: Fosfato | C31: Diaria | D31: 30 - 60 mg/l | E31: 50 | F31: 52.5
B32: TDS | C32: Diaria | D32: − | E32: 2912 | F32: 2475
A34: Caldera N°2 | B34: Alcalinidad +M en CaCO3 | C34: Semanal | D34: ≤ 700 mg/l
B35: Alcalinidad OH¯ en CaCO3 | C35: Semanal | D35: ≥ 40 mg/l
B36: Conductividad | C36: Diaria | D36: 1.100 - 1.500 uS/cm | E36: 3498 | F36: 3170
B37: pH | C37: Diaria | D37: 10,5 - 11,9 | E37: 11.9 | F37: 11.8
B38: Sílice en SiO2 | C38: Semanal | D38: ≤ 150 mg/l
B39: Dureza Total en CaCO3 | C39: Semanal | D39: ˂ 3 mg/l
B40: Hierro Total | C40: Mensual | D40: ˂ 1 mg/l
B41: Sulfito | C41: Diaria | D41: 30 - 60 mg/l | E41: 48 | F41: 52
B42: Fosfato | C42: Diaria | D42: 30 - 60 mg/l | E42: 45 | F42: 60
B43: TDS | C43: Diaria | D43: − | E43: 2586 | F43: 2309
A45: Caldera N°3 | B45: Alcalinidad +M en CaCO3 | C45: Semanal | D45: ≤ 700 mg/l
B46: Alcalinidad OH¯ en CaCO3 | C46: Semanal | D46: ≥ 40 mg/l
B47: Conductividad | C47: Diaria | D47: 1.100 - 1.500 uS/cm | E47: 1583 | F47: 1956
...

Sheet  06-03-26
C2: VARIABLE DE CONTROL SISTEMA DE GENERACIÓN DE VAPOR " PLANTA SALSAS Y UNTABLES" | H2: Codigo: FOXXX-0704-MAN
H3: Fecha actualización: XX/XX/XXXX
H4: Versión: X
A6: NOMBRE DE LA PLANTA: Alimentos Polar Comercial, C.A. Salsas y Untables
A7: DIRECCIÓN: Avenida Luis Ernesto Branger, Zona Industrial Norte II, Parroquia Rafael Urdaneta, Valencia, Edo. Carabobo,
A8: Venezuela. Código postal 2001.
A11: FECHA: | B11: 46087 | C11: Nombre y Apellido | E11: Angel M | F11: Arturo C | G11: Observaciones
A12: Area | B12: Variable de control | D12: Rango Operación | E12: 1er Turno | F12: 2do Turno
E13: 0.29166667 | F13: 0.79166667
A14: Alimentación Calderas | B14: Hierro Total | C14: Semanal | D14: ≤ 0,1 mg/l
B15: Temperatura | C15: Diaria | D15: ≥ 104 °C | E15: 93.4 | F15: 92.2
B16: Dureza Total en CaCO3 | C16: Diaria | D16: ≤ 0,3 mg/l
B17: Conductividad | C17: Semanal | D17: − | E17: 560 | F17: 603
B18: pH | C18: Diaria | D18: 8,5 - 10,0 | E18: 7.6 | F18: 8.03
B19: Sílice en SiO2 | C19: Semanal | D19: −
B20: Alcalinidad +M en CaCO3 | C20: Semanal | D20: −
B21: Alcalinidad OH¯ en CaCO3 | C21: Semanal | D21: −
A23: Caldera N°1 | B23: Alcalinidad +M en CaCO3 | C23: Semanal | D23: ≤ 700 mg/l
B24: Alcalinidad OH¯ en CaCO3 | C24: Semanal | D24: ≥ 40 mg/l
B25: Conductividad | C25: Diaria | D25: 1.100 - 1.500 uS/cm | E25: 3295 | F25: 3670
B26: pH | C26: Diaria | D26: 10,5 - 11,9 | E26: 11.7 | F26: 12.02
B27: Sílice en SiO2 | C27: Semanal | D27: ≤ 150 mg/l
B28: Dureza Total en CaCO3 | C28: Semanal | D28: ˂ 3 mg/l
B29: Hierro Total | C29: Mensual | D29: ˂ 1 mg/l
B30: Sulfito | C30: Diaria | D30: 30 - 60 mg/l | E30: 60 | F30: 42
B31: Fosfato | C31: Diaria | D31: 30 - 60 mg/l | E31: 52.5 | F31: 35
B32: TDS | C32: Diaria | D32: − | E32: 2159 | F32: 2509
A34: Caldera N°2 | B34: Alcalinidad +M en CaCO3 | C34: Semanal | D34: ≤ 700 mg/l
B35: Alcalinidad OH¯ en CaCO3 | C35: Semanal | D35: ≥ 40 mg/l
B36: Conductividad | C36: Diaria | D36: 1.100 - 1.500 uS/cm | E36: 2966 | F36: 3399
B37: pH | C37: Diaria | D37: 10,5 - 11,9 | E37: 11.75 | F37: 12
B38: Sílice en SiO2 | C38: Semanal | D38: ≤ 150 mg/l
B39: Dureza Total en CaCO3 | C39: Semanal | D39: ˂ 3 mg/l
B40: Hierro Total | C40: Mensual | D40: ˂ 1 mg/l
B41: Sulfito | C41: Diaria | D41: 30 - 60 mg/l | E41: 60 | F41: 42
B42: Fosfato | C42: Diaria | D42: 30 - 60 mg/l | E42: 52.5 | F42: 32.5
B43: TDS | C43: Diaria | D43: − | E43: 2159 | F43: 1977
A45: Caldera N°3 | B45: Alcalinidad +M en CaCO3 | C45: Semanal | D45: ≤ 700 mg/l
B46: Alcalinidad OH¯ en CaCO3 | C46: Semanal | D46: ≥ 40 mg/l
B47: Conductividad | C47: Diaria | D47: 1.100 - 1.500 uS/cm | E47: 2491 | F47: 2705
...

Sheet  07-03-26
C2: VARIABLE DE CONTROL SISTEMA DE GENERACIÓN DE VAPOR " PLANTA SALSAS Y UNTABLES" | H2: Codigo: FOXXX-0704-MAN
H3: Fecha actualización: XX/XX/XXXX
H4: Versión: X
A6: NOMBRE DE LA PLANTA: Alimentos Polar Comercial, C.A. Salsas y Untables
A7: DIRECCIÓN: Avenida Luis Ernesto Branger, Zona Industrial Norte II, Parroquia Rafael Urdaneta, Valencia, Edo. Carabobo,
A8: Venezuela. Código postal 2001.
A11: FECHA: | B11: 46088 | C11: Nombre y Apellido | E11: Angel M | F11: Arturo C | G11: Observaciones
A12: Area | B12: Variable de control | D12: Rango Operación | E12: 1er Turno | F12: 2do Turno
E13: 0.29166667 | F13: 0.79166667
A14: Alimentación Calderas | B14: Hierro Total | C14: Semanal | D14: ≤ 0,1 mg/l
B15: Temperatura | C15: Diaria | D15: ≥ 104 °C | E15: 92.4 | F15: 91.2
B16: Dureza Total en CaCO3 | C16: Diaria | D16: ≤ 0,3 mg/l
B17: Conductividad | C17: Semanal | D17: − | F17: 592
B18: pH | C18: Diaria | D18: 8,5 - 10,0 | E18: 7.42 | F18: 7.94
B19: Sílice en SiO2 | C19: Semanal | D19: −
B20: Alcalinidad +M en CaCO3 | C20: Semanal | D20: −
B21: Alcalinidad OH¯ en CaCO3 | C21: Semanal | D21: −
A23: Caldera N°1 | B23: Alcalinidad +M en CaCO3 | C23: Semanal | D23: ≤ 700 mg/l
B24: Alcalinidad OH¯ en CaCO3 | C24: Semanal | D24: ≥ 40 mg/l
B25: Conductividad | C25: Diaria | D25: 1.100 - 1.500 uS/cm | E25: 3675 | F25: 3737
B26: pH | C26: Diaria | D26: 10,5 - 11,9 | E26: 11.5 | F26: 11.85
B27: Sílice en SiO2 | C27: Semanal | D27: ≤ 150 mg/l
B28: Dureza Total en CaCO3 | C28: Semanal | D28: ˂ 3 mg/l
B29: Hierro Total | C29: Mensual | D29: ˂ 1 mg/l
B30: Sulfito | C30: Diaria | D30: 30 - 60 mg/l | E30: 97 | F30: 46
B31: Fosfato | C31: Diaria | D31: 30 - 60 mg/l | E31: 82.5
B32: TDS | C32: Diaria | D32: − | E32: 2420 | F32: 2568
A34: Caldera N°2 | B34: Alcalinidad +M en CaCO3 | C34: Semanal | D34: ≤ 700 mg/l
B35: Alcalinidad OH¯ en CaCO3 | C35: Semanal | D35: ≥ 40 mg/l
B36: Conductividad | C36: Diaria | D36: 1.100 - 1.500 uS/cm | E36: 3303 | F36: 3488
B37: pH | C37: Diaria | D37: 10,5 - 11,9 | E37: 11.5 | F37: 11.9
B38: Sílice en SiO2 | C38: Semanal | D38: ≤ 150 mg/l
B39: Dureza Total en CaCO3 | C39: Semanal | D39: ˂ 3 mg/l
B40: Hierro Total | C40: Mensual | D40: ˂ 1 mg/l
B41: Sulfito | C41: Diaria | D41: 30 - 60 mg/l | E41: 50 | F41: 30
B42: Fosfato | C42: Diaria | D42: 30 - 60 mg/l | E42: 42.5
B43: TDS | C43: Diaria | D43: − | E43: 2216 | F43: 2568
A45: Caldera N°3 | B45: Alcalinidad +M en CaCO3 | C45: Semanal | D45: ≤ 700 mg/l
B46: Alcalinidad OH¯ en CaCO3 | C46: Semanal | D46: ≥ 40 mg/l
B47: Conductividad | C47: Diaria | D47: 1.100 - 1.500 uS/cm | E47: 3083 | F47: 2941
...

Sheet  08-03-26
C2: VARIABLE DE CONTROL SISTEMA DE GENERACIÓN DE VAPOR " PLANTA SALSAS Y UNTABLES" | H2: Codigo: FOXXX-0704-MAN
H3: Fecha actualización: XX/XX/XXXX
H4: Versión: X
A6: NOMBRE DE LA PLANTA: Alimentos Polar Comercial, C.A. Salsas y Untables
A7: DIRECCIÓN: Avenida Luis Ernesto Branger, Zona Industrial Norte II, Parroquia Rafael Urdaneta, Valencia, Edo. Carabobo,
A8: Venezuela. Código postal 2001.
A11: FECHA: | B11: 46089 | C11: Nombre y Apellido | E11: Eliezer D | F11: Angel M | G11: Observaciones
A12: Area | B12: Variable de control | D12: Rango Operación | E12: 1er Turno | F12: 2do Turno
E13: 0.29166667 | F13: 0.79166667
A14: Alimentación Calderas | B14: Hierro Total | C14: Semanal | D14: ≤ 0,1 mg/l
B15: Temperatura | C15: Diaria | D15: ≥ 104 °C | E15: 93.8 | F15: 93.1
B16: Dureza Total en CaCO3 | C16: Diaria | D16: ≤ 0,3 mg/l
B17: Conductividad | C17: Semanal | D17: −
B18: pH | C18: Diaria | D18: 8,5 - 10,0 | E18: 7.62 | F18: 7.73
B19: Sílice en SiO2 | C19: Semanal | D19: −
B20: Alcalinidad +M en CaCO3 | C20: Semanal | D20: −
B21: Alcalinidad OH¯ en CaCO3 | C21: Semanal | D21: −
A23: Caldera N°1 | B23: Alcalinidad +M en CaCO3 | C23: Semanal | D23: ≤ 700 mg/l
B24: Alcalinidad OH¯ en CaCO3 | C24: Semanal | D24: ≥ 40 mg/l
B25: Conductividad | C25: Diaria | D25: 1.100 - 1.500 uS/cm | E25: 4916 | F25: 3955
B26: pH | C26: Diaria | D26: 10,5 - 11,9 | E26: 11.89 | F26: 11.45
B27: Sílice en SiO2 | C27: Semanal | D27: ≤ 150 mg/l
B28: Dureza Total en CaCO3 | C28: Semanal | D28: ˂ 3 mg/l
B29: Hierro Total | C29: Mensual | D29: ˂ 1 mg/l
B30: Sulfito | C30: Diaria | D30: 30 - 60 mg/l | E30: 55 | F30: 42
B31: Fosfato | C31: Diaria | D31: 30 - 60 mg/l
B32: TDS | C32: Diaria | D32: − | E32: 3792 | F32: 9247
A34: Caldera N°2 | B34: Alcalinidad +M en CaCO3 | C34: Semanal | D34: ≤ 700 mg/l
B35: Alcalinidad OH¯ en CaCO3 | C35: Semanal | D35: ≥ 40 mg/l
B36: Conductividad | C36: Diaria | D36: 1.100 - 1.500 uS/cm | E36: 5009 | F36: 3315
B37: pH | C37: Diaria | D37: 10,5 - 11,9 | E37: 11.9 | F37: 11.65
B38: Sílice en SiO2 | C38: Semanal | D38: ≤ 150 mg/l
B39: Dureza Total en CaCO3 | C39: Semanal | D39: ˂ 3 mg/l
B40: Hierro Total | C40: Mensual | D40: ˂ 1 mg/l
B41: Sulfito | C41: Diaria | D41: 30 - 60 mg/l | E41: 34 | F41: 40
B42: Fosfato | C42: Diaria | D42: 30 - 60 mg/l
B43: TDS | C43: Diaria | D43: − | E43: 2842 | F43: 2435
A45: Caldera N°3 | B45: Alcalinidad +M en CaCO3 | C45: Semanal | D45: ≤ 700 mg/l
B46: Alcalinidad OH¯ en CaCO3 | C46: Semanal | D46: ≥ 40 mg/l
B47: Conductividad | C47: Diaria | D47: 1.100 - 1.500 uS/cm | E47: 3828 | F47: 2469
...

Sheet  09-03-26
C2: VARIABLE DE CONTROL SISTEMA DE GENERACIÓN DE VAPOR " PLANTA SALSAS Y UNTABLES" | H2: Codigo: FOXXX-0704-MAN
H3: Fecha actualización: XX/XX/XXXX
H4: Versión: X
A6: NOMBRE DE LA PLANTA: Alimentos Polar Comercial, C.A. Salsas y Untables
A7: DIRECCIÓN: Avenida Luis Ernesto Branger, Zona Industrial Norte II, Parroquia Rafael Urdaneta, Valencia, Edo. Carabobo,
A8: Venezuela. Código postal 2001.
A11: FECHA: | B11: 46090 | C11: Nombre y Apellido | E11: Eliezer D | F11: Angel M | G11: Observaciones
A12: Area | B12: Variable de control | D12: Rango Operación | E12: 1er Turno | F12: 2do Turno
E13: 0.29166667 | F13: 0.79166667
A14: Alimentación Calderas | B14: Hierro Total | C14: Semanal | D14: ≤ 0,1 mg/l
B15: Temperatura | C15: Diaria | D15: ≥ 104 °C | E15: 94.2 | F15: 94.1
B16: Dureza Total en CaCO3 | C16: Diaria | D16: ≤ 0,3 mg/l
B17: Conductividad | C17: Semanal | D17: −
B18: pH | C18: Diaria | D18: 8,5 - 10,0 | E18: 7.63 | F18: 7.67
B19: Sílice en SiO2 | C19: Semanal | D19: −
B20: Alcalinidad +M en CaCO3 | C20: Semanal | D20: −
B21: Alcalinidad OH¯ en CaCO3 | C21: Semanal | D21: −
A23: Caldera N°1 | B23: Alcalinidad +M en CaCO3 | C23: Semanal | D23: ≤ 700 mg/l
B24: Alcalinidad OH¯ en CaCO3 | C24: Semanal | D24: ≥ 40 mg/l
B25: Conductividad | C25: Diaria | D25: 1.100 - 1.500 uS/cm | E25: 3647 | F25: 3438
B26: pH | C26: Diaria | D26: 10,5 - 11,9 | E26: 11.9 | F26: 11.87
B27: Sílice en SiO2 | C27: Semanal | D27: ≤ 150 mg/l
B28: Dureza Total en CaCO3 | C28: Semanal | D28: ˂ 3 mg/l
B29: Hierro Total | C29: Mensual | D29: ˂ 1 mg/l
B30: Sulfito | C30: Diaria | D30: 30 - 60 mg/l | E30: 58 | F30: 55
B31: Fosfato | C31: Diaria | D31: 30 - 60 mg/l
B32: TDS | C32: Diaria | D32: −
A34: Caldera N°2 | B34: Alcalinidad +M en CaCO3 | C34: Semanal | D34: ≤ 700 mg/l
B35: Alcalinidad OH¯ en CaCO3 | C35: Semanal | D35: ≥ 40 mg/l
B36: Conductividad | C36: Diaria | D36: 1.100 - 1.500 uS/cm | E36: 3253 | F36: 3428
B37: pH | C37: Diaria | D37: 10,5 - 11,9 | E37: 11.89 | F37: 11.79
B38: Sílice en SiO2 | C38: Semanal | D38: ≤ 150 mg/l
B39: Dureza Total en CaCO3 | C39: Semanal | D39: ˂ 3 mg/l
B40: Hierro Total | C40: Mensual | D40: ˂ 1 mg/l
B41: Sulfito | C41: Diaria | D41: 30 - 60 mg/l | E41: 36 | F41: 32
B42: Fosfato | C42: Diaria | D42: 30 - 60 mg/l
B43: TDS | C43: Diaria | D43: − | E43: 2385 | F43: 2464
A45: Caldera N°3 | B45: Alcalinidad +M en CaCO3 | C45: Semanal | D45: ≤ 700 mg/l
B46: Alcalinidad OH¯ en CaCO3 | C46: Semanal | D46: ≥ 40 mg/l
B47: Conductividad | C47: Diaria | D47: 1.100 - 1.500 uS/cm | E47: 2129 | F47: 2226
...

Sheet  10-03-26
C2: VARIABLE DE CONTROL SISTEMA DE GENERACIÓN DE VAPOR " PLANTA SALSAS Y UNTABLES" | H2: Codigo: FOXXX-0704-MAN
H3: Fecha actualización: XX/XX/XXXX
H4: Versión: X
A6: NOMBRE DE LA PLANTA: Alimentos Polar Comercial, C.A. Salsas y Untables
A7: DIRECCIÓN: Avenida Luis Ernesto Branger, Zona Industrial Norte II, Parroquia Rafael Urdaneta, Valencia, Edo. Carabobo,
A8: Venezuela. Código postal 2001.
A11: FECHA: | B11: 46091 | C11: Nombre y Apellido | E11: Osman A | F11: Eliezer D | G11: Observaciones
A12: Area | B12: Variable de control | D12: Rango Operación | E12: 1er Turno | F12: 2do Turno
E13: 0.29166667 | F13: 0.79166667
A14: Alimentación Calderas | B14: Hierro Total | C14: Semanal | D14: ≤ 0,1 mg/l
B15: Temperatura | C15: Diaria | D15: ≥ 104 °C | E15: 92.8 | F15: 92
B16: Dureza Total en CaCO3 | C16: Diaria | D16: ≤ 0,3 mg/l
B17: Conductividad | C17: Semanal | D17: − | E17: 602
B18: pH | C18: Diaria | D18: 8,5 - 10,0 | E18: 7.87 | F18: 7.69
B19: Sílice en SiO2 | C19: Semanal | D19: −
B20: Alcalinidad +M en CaCO3 | C20: Semanal | D20: − | E20: 280
B21: Alcalinidad OH¯ en CaCO3 | C21: Semanal | D21: −
A23: Caldera N°1 | B23: Alcalinidad +M en CaCO3 | C23: Semanal | D23: ≤ 700 mg/l | E23: 1064
B24: Alcalinidad OH¯ en CaCO3 | C24: Semanal | D24: ≥ 40 mg/l | E24: 584
B25: Conductividad | C25: Diaria | D25: 1.100 - 1.500 uS/cm | E25: 3536 | F25: 3589
B26: pH | C26: Diaria | D26: 10,5 - 11,9 | E26: 11.76 | F26: 11.89
B27: Sílice en SiO2 | C27: Semanal | D27: ≤ 150 mg/l
B28: Dureza Total en CaCO3 | C28: Semanal | D28: ˂ 3 mg/l
B29: Hierro Total | C29: Mensual | D29: ˂ 1 mg/l
B30: Sulfito | C30: Diaria | D30: 30 - 60 mg/l | E30: 36 | F30: 45
B31: Fosfato | C31: Diaria | D31: 30 - 60 mg/l
B32: TDS | C32: Diaria | D32: − | E32: 2609 | F32: 2683
A34: Caldera N°2 | B34: Alcalinidad +M en CaCO3 | C34: Semanal | D34: ≤ 700 mg/l | E34: 960
B35: Alcalinidad OH¯ en CaCO3 | C35: Semanal | D35: ≥ 40 mg/l | E35: 512
B36: Conductividad | C36: Diaria | D36: 1.100 - 1.500 uS/cm | E36: 3397 | F36: 3372
B37: pH | C37: Diaria | D37: 10,5 - 11,9 | E37: 11.9 | F37: 11.9
B38: Sílice en SiO2 | C38: Semanal | D38: ≤ 150 mg/l
B39: Dureza Total en CaCO3 | C39: Semanal | D39: ˂ 3 mg/l
B40: Hierro Total | C40: Mensual | D40: ˂ 1 mg/l
B41: Sulfito | C41: Diaria | D41: 30 - 60 mg/l | E41: 38 | F41: 34
B42: Fosfato | C42: Diaria | D42: 30 - 60 mg/l
B43: TDS | C43: Diaria | D43: − | E43: 2498 | F43: 2484
A45: Caldera N°3 | B45: Alcalinidad +M en CaCO3 | C45: Semanal | D45: ≤ 700 mg/l | E45: 572
B46: Alcalinidad OH¯ en CaCO3 | C46: Semanal | D46: ≥ 40 mg/l | E46: 236
B47: Conductividad | C47: Diaria | D47: 1.100 - 1.500 uS/cm | E47: 1862 | F47: 2058
...

Sheet  11-03-26
C2: VARIABLE DE CONTROL SISTEMA DE GENERACIÓN DE VAPOR " PLANTA SALSAS Y UNTABLES" | H2: Codigo: FOXXX-0704-MAN
H3: Fecha actualización: XX/XX/XXXX
H4: Versión: X
A6: NOMBRE DE LA PLANTA: Alimentos Polar Comercial, C.A. Salsas y Untables
A7: DIRECCIÓN: Avenida Luis Ernesto Branger, Zona Industrial Norte II, Parroquia Rafael Urdaneta, Valencia, Edo. Carabobo,
A8: Venezuela. Código postal 2001.
A11: FECHA: | B11: 46092 | C11: Nombre y Apellido | E11: Osman A | F11: Eliezer D | G11: Observaciones
A12: Area | B12: Variable de control | D12: Rango Operación | E12: 1er Turno | F12: 2do Turno
E13: 0.29166667 | F13: 0.79166667
A14: Alimentación Calderas | B14: Hierro Total | C14: Semanal | D14: ≤ 0,1 mg/l
B15: Temperatura | C15: Diaria | D15: ≥ 104 °C | E15: 91.6 | F15: 93.5
B16: Dureza Total en CaCO3 | C16: Diaria | D16: ≤ 0,3 mg/l
B17: Conductividad | C17: Semanal | D17: −
B18: pH | C18: Diaria | D18: 8,5 - 10,0 | E18: 7.72 | F18: 7.69
B19: Sílice en SiO2 | C19: Semanal | D19: −
B20: Alcalinidad +M en CaCO3 | C20: Semanal | D20: −
B21: Alcalinidad OH¯ en CaCO3 | C21: Semanal | D21: −
A23: Caldera N°1 | B23: Alcalinidad +M en CaCO3 | C23: Semanal | D23: ≤ 700 mg/l
B24: Alcalinidad OH¯ en CaCO3 | C24: Semanal | D24: ≥ 40 mg/l
B25: Conductividad | C25: Diaria | D25: 1.100 - 1.500 uS/cm | E25: 3800 | F25: 3946
B26: pH | C26: Diaria | D26: 10,5 - 11,9 | E26: 11.83 | F26: 11.9
B27: Sílice en SiO2 | C27: Semanal | D27: ≤ 150 mg/l
B28: Dureza Total en CaCO3 | C28: Semanal | D28: ˂ 3 mg/l
B29: Hierro Total | C29: Mensual | D29: ˂ 1 mg/l
B30: Sulfito | C30: Diaria | D30: 30 - 60 mg/l | E30: 43 | F30: 52
B31: Fosfato | C31: Diaria | D31: 30 - 60 mg/l
B32: TDS | C32: Diaria | D32: − | E32: 2824 | F32: 2944
A34: Caldera N°2 | B34: Alcalinidad +M en CaCO3 | C34: Semanal | D34: ≤ 700 mg/l
B35: Alcalinidad OH¯ en CaCO3 | C35: Semanal | D35: ≥ 40 mg/l
B36: Conductividad | C36: Diaria | D36: 1.100 - 1.500 uS/cm | E36: 3461 | F36: 3480
B37: pH | C37: Diaria | D37: 10,5 - 11,9 | E37: 11.89 | F37: 11.88
B38: Sílice en SiO2 | C38: Semanal | D38: ≤ 150 mg/l
B39: Dureza Total en CaCO3 | C39: Semanal | D39: ˂ 3 mg/l
B40: Hierro Total | C40: Mensual | D40: ˂ 1 mg/l
B41: Sulfito | C41: Diaria | D41: 30 - 60 mg/l | E41: 32 | F41: 36
B42: Fosfato | C42: Diaria | D42: 30 - 60 mg/l
B43: TDS | C43: Diaria | D43: − | E43: 2550 | F43: 2575
A45: Caldera N°3 | B45: Alcalinidad +M en CaCO3 | C45: Semanal | D45: ≤ 700 mg/l
B46: Alcalinidad OH¯ en CaCO3 | C46: Semanal | D46: ≥ 40 mg/l
B47: Conductividad | C47: Diaria | D47: 1.100 - 1.500 uS/cm | E47: 2356 | F47: 2537
...

Sheet  12-03-26
C2: VARIABLE DE CONTROL SISTEMA DE GENERACIÓN DE VAPOR " PLANTA SALSAS Y UNTABLES" | H2: Codigo: FOXXX-0704-MAN
H3: Fecha actualización: XX/XX/XXXX
H4: Versión: X
A6: NOMBRE DE LA PLANTA: Alimentos Polar Comercial, C.A. Salsas y Untables
A7: DIRECCIÓN: Avenida Luis Ernesto Branger, Zona Industrial Norte II, Parroquia Rafael Urdaneta, Valencia, Edo. Carabobo,
A8: Venezuela. Código postal 2001.
A11: FECHA: | C11: Nombre y Apellido | G11: Observaciones
A12: Area | B12: Variable de control | D12: Rango Operación | E12: 1er Turno | F12: 2do Turno
E13: 0.29166667 | F13: 0.79166667
A14: Alimentación Calderas | B14: Hierro Total | C14: Semanal | D14: ≤ 0,1 mg/l
B15: Temperatura | C15: Diaria | D15: ≥ 104 °C
B16: Dureza Total en CaCO3 | C16: Diaria | D16: ≤ 0,3 mg/l
B17: Conductividad | C17: Semanal | D17: −
B18: pH | C18: Diaria | D18: 8,5 - 10,0
B19: Sílice en SiO2 | C19: Semanal | D19: −
B20: Alcalinidad +M en CaCO3 | C20: Semanal | D20: −
B21: Alcalinidad OH¯ en CaCO3 | C21: Semanal | D21: −
A23: Caldera N°1 | B23: Alcalinidad +M en CaCO3 | C23: Semanal | D23: ≤ 700 mg/l
B24: Alcalinidad OH¯ en CaCO3 | C24: Semanal | D24: ≥ 40 mg/l
B25: Conductividad | C25: Diaria | D25: 1.100 - 1.500 uS/cm
B26: pH | C26: Diaria | D26: 10,5 - 11,9
B27: Sílice en SiO2 | C27: Semanal | D27: ≤ 150 mg/l
B28: Dureza Total en CaCO3 | C28: Semanal | D28: ˂ 3 mg/l
B29: Hierro Total | C29: Mensual | D29: ˂ 1 mg/l
B30: Sulfito | C30: Diaria | D30: 30 - 60 mg/l
B31: Fosfato | C31: Diaria | D31: 30 - 60 mg/l
B32: TDS | C32: Diaria | D32: −
A34: Caldera N°2 | B34: Alcalinidad +M en CaCO3 | C34: Semanal | D34: ≤ 700 mg/l
B35: Alcalinidad OH¯ en CaCO3 | C35: Semanal | D35: ≥ 40 mg/l
B36: Conductividad | C36: Diaria | D36: 1.100 - 1.500 uS/cm
B37: pH | C37: Diaria | D37: 10,5 - 11,9
B38: Sílice en SiO2 | C38: Semanal | D38: ≤ 150 mg/l
B39: Dureza Total en CaCO3 | C39: Semanal | D39: ˂ 3 mg/l
B40: Hierro Total | C40: Mensual | D40: ˂ 1 mg/l
B41: Sulfito | C41: Diaria | D41: 30 - 60 mg/l
B42: Fosfato | C42: Diaria | D42: 30 - 60 mg/l
B43: TDS | C43: Diaria | D43: −
A45: Caldera N°3 | B45: Alcalinidad +M en CaCO3 | C45: Semanal | D45: ≤ 700 mg/l
B46: Alcalinidad OH¯ en CaCO3 | C46: Semanal | D46: ≥ 40 mg/l
B47: Conductividad | C47: Diaria | D47: 1.100 - 1.500 uS/cm
...

Sheet  13-03-26
C2: VARIABLE DE CONTROL SISTEMA DE GENERACIÓN DE VAPOR " PLANTA SALSAS Y UNTABLES" | H2: Codigo: FOXXX-0704-MAN
H3: Fecha actualización: XX/XX/XXXX
H4: Versión: X
A6: NOMBRE DE LA PLANTA: Alimentos Polar Comercial, C.A. Salsas y Untables
A7: DIRECCIÓN: Avenida Luis Ernesto Branger, Zona Industrial Norte II, Parroquia Rafael Urdaneta, Valencia, Edo. Carabobo,
A8: Venezuela. Código postal 2001.
A11: FECHA: | C11: Nombre y Apellido | G11: Observaciones
A12: Area | B12: Variable de control | D12: Rango Operación | E12: 1er Turno | F12: 2do Turno
E13: 0.29166667 | F13: 0.79166667
A14: Alimentación Calderas | B14: Hierro Total | C14: Semanal | D14: ≤ 0,1 mg/l
B15: Temperatura | C15: Diaria | D15: ≥ 104 °C
B16: Dureza Total en CaCO3 | C16: Diaria | D16: ≤ 0,3 mg/l
B17: Conductividad | C17: Semanal | D17: −
B18: pH | C18: Diaria | D18: 8,5 - 10,0
B19: Sílice en SiO2 | C19: Semanal | D19: −
B20: Alcalinidad +M en CaCO3 | C20: Semanal | D20: −
B21: Alcalinidad OH¯ en CaCO3 | C21: Semanal | D21: −
A23: Caldera N°1 | B23: Alcalinidad +M en CaCO3 | C23: Semanal | D23: ≤ 700 mg/l
B24: Alcalinidad OH¯ en CaCO3 | C24: Semanal | D24: ≥ 40 mg/l
B25: Conductividad | C25: Diaria | D25: 1.100 - 1.500 uS/cm
B26: pH | C26: Diaria | D26: 10,5 - 11,9
B27: Sílice en SiO2 | C27: Semanal | D27: ≤ 150 mg/l
B28: Dureza Total en CaCO3 | C28: Semanal | D28: ˂ 3 mg/l
B29: Hierro Total | C29: Mensual | D29: ˂ 1 mg/l
B30: Sulfito | C30: Diaria | D30: 30 - 60 mg/l
B31: Fosfato | C31: Diaria | D31: 30 - 60 mg/l
B32: TDS | C32: Diaria | D32: −
A34: Caldera N°2 | B34: Alcalinidad +M en CaCO3 | C34: Semanal | D34: ≤ 700 mg/l
B35: Alcalinidad OH¯ en CaCO3 | C35: Semanal | D35: ≥ 40 mg/l
B36: Conductividad | C36: Diaria | D36: 1.100 - 1.500 uS/cm
B37: pH | C37: Diaria | D37: 10,5 - 11,9
B38: Sílice en SiO2 | C38: Semanal | D38: ≤ 150 mg/l
B39: Dureza Total en CaCO3 | C39: Semanal | D39: ˂ 3 mg/l
B40: Hierro Total | C40: Mensual | D40: ˂ 1 mg/l
B41: Sulfito | C41: Diaria | D41: 30 - 60 mg/l
B42: Fosfato | C42: Diaria | D42: 30 - 60 mg/l
B43: TDS | C43: Diaria | D43: −
A45: Caldera N°3 | B45: Alcalinidad +M en CaCO3 | C45: Semanal | D45: ≤ 700 mg/l
B46: Alcalinidad OH¯ en CaCO3 | C46: Semanal | D46: ≥ 40 mg/l
B47: Conductividad | C47: Diaria | D47: 1.100 - 1.500 uS/cm
...

Sheet  14-03-26
C2: VARIABLE DE CONTROL SISTEMA DE GENERACIÓN DE VAPOR " PLANTA SALSAS Y UNTABLES" | H2: Codigo: FOXXX-0704-MAN
H3: Fecha actualización: XX/XX/XXXX
H4: Versión: X
A6: NOMBRE DE LA PLANTA: Alimentos Polar Comercial, C.A. Salsas y Untables
A7: DIRECCIÓN: Avenida Luis Ernesto Branger, Zona Industrial Norte II, Parroquia Rafael Urdaneta, Valencia, Edo. Carabobo,
A8: Venezuela. Código postal 2001.
A11: FECHA: | B11: 46095 | C11: Nombre y Apellido | E11: Angel M | F11: Arturo C | G11: Observaciones
A12: Area | B12: Variable de control | D12: Rango Operación | E12: 1er Turno | F12: 2do Turno
E13: 0.29166667 | F13: 0.79166667
A14: Alimentación Calderas | B14: Hierro Total | C14: Semanal | D14: ≤ 0,1 mg/l
B15: Temperatura | C15: Diaria | D15: ≥ 104 °C | E15: 93.4 | F15: 93.5
B16: Dureza Total en CaCO3 | C16: Diaria | D16: ≤ 0,3 mg/l
B17: Conductividad | C17: Semanal | D17: − | E17: 539
B18: pH | C18: Diaria | D18: 8,5 - 10,0 | E18: 7.61 | F18: 7.96
B19: Sílice en SiO2 | C19: Semanal | D19: −
B20: Alcalinidad +M en CaCO3 | C20: Semanal | D20: −
B21: Alcalinidad OH¯ en CaCO3 | C21: Semanal | D21: −
A23: Caldera N°1 | B23: Alcalinidad +M en CaCO3 | C23: Semanal | D23: ≤ 700 mg/l
B24: Alcalinidad OH¯ en CaCO3 | C24: Semanal | D24: ≥ 40 mg/l
B25: Conductividad | C25: Diaria | D25: 1.100 - 1.500 uS/cm | E25: 3436
B26: pH | C26: Diaria | D26: 10,5 - 11,9 | E26: 11.74 | F26: 11.86
B27: Sílice en SiO2 | C27: Semanal | D27: ≤ 150 mg/l
B28: Dureza Total en CaCO3 | C28: Semanal | D28: ˂ 3 mg/l
B29: Hierro Total | C29: Mensual | D29: ˂ 1 mg/l
B30: Sulfito | C30: Diaria | D30: 30 - 60 mg/l | E30: 48 | F30: 70
B31: Fosfato | C31: Diaria | D31: 30 - 60 mg/l | E31: 45 | F31: 42.5
B32: TDS | C32: Diaria | D32: − | E32: 2710
A34: Caldera N°2 | B34: Alcalinidad +M en CaCO3 | C34: Semanal | D34: ≤ 700 mg/l
B35: Alcalinidad OH¯ en CaCO3 | C35: Semanal | D35: ≥ 40 mg/l
B36: Conductividad | C36: Diaria | D36: 1.100 - 1.500 uS/cm | E36: 3244
B37: pH | C37: Diaria | D37: 10,5 - 11,9 | E37: 11.8 | F37: 11.84
B38: Sílice en SiO2 | C38: Semanal | D38: ≤ 150 mg/l
B39: Dureza Total en CaCO3 | C39: Semanal | D39: ˂ 3 mg/l
B40: Hierro Total | C40: Mensual | D40: ˂ 1 mg/l
B41: Sulfito | C41: Diaria | D41: 30 - 60 mg/l | E41: 34 | F41: 58
B42: Fosfato | C42: Diaria | D42: 30 - 60 mg/l | E42: 32.5 | F42: 50
B43: TDS | C43: Diaria | D43: − | E43: 2890
A45: Caldera N°3 | B45: Alcalinidad +M en CaCO3 | C45: Semanal | D45: ≤ 700 mg/l
B46: Alcalinidad OH¯ en CaCO3 | C46: Semanal | D46: ≥ 40 mg/l
B47: Conductividad | C47: Diaria | D47: 1.100 - 1.500 uS/cm | E47: 3022
...

Sheet  15-03-26
C2: VARIABLE DE CONTROL SISTEMA DE GENERACIÓN DE VAPOR " PLANTA SALSAS Y UNTABLES" | H2: Codigo: FOXXX-0704-MAN
H3: Fecha actualización: XX/XX/XXXX
H4: Versión: X
A6: NOMBRE DE LA PLANTA: Alimentos Polar Comercial, C.A. Salsas y Untables
A7: DIRECCIÓN: Avenida Luis Ernesto Branger, Zona Industrial Norte II, Parroquia Rafael Urdaneta, Valencia, Edo. Carabobo,
A8: Venezuela. Código postal 2001.
A11: FECHA: | C11: Nombre y Apellido | G11: Observaciones
A12: Area | B12: Variable de control | D12: Rango Operación | E12: 1er Turno | F12: 2do Turno
E13: 0.29166667 | F13: 0.79166667
A14: Alimentación Calderas | B14: Hierro Total | C14: Semanal | D14: ≤ 0,1 mg/l
B15: Temperatura | C15: Diaria | D15: ≥ 104 °C
B16: Dureza Total en CaCO3 | C16: Diaria | D16: ≤ 0,3 mg/l
B17: Conductividad | C17: Semanal | D17: −
B18: pH | C18: Diaria | D18: 8,5 - 10,0
B19: Sílice en SiO2 | C19: Semanal | D19: −
B20: Alcalinidad +M en CaCO3 | C20: Semanal | D20: −
B21: Alcalinidad OH¯ en CaCO3 | C21: Semanal | D21: −
A23: Caldera N°1 | B23: Alcalinidad +M en CaCO3 | C23: Semanal | D23: ≤ 700 mg/l
B24: Alcalinidad OH¯ en CaCO3 | C24: Semanal | D24: ≥ 40 mg/l
B25: Conductividad | C25: Diaria | D25: 1.100 - 1.500 uS/cm
B26: pH | C26: Diaria | D26: 10,5 - 11,9
B27: Sílice en SiO2 | C27: Semanal | D27: ≤ 150 mg/l
B28: Dureza Total en CaCO3 | C28: Semanal | D28: ˂ 3 mg/l
B29: Hierro Total | C29: Mensual | D29: ˂ 1 mg/l
B30: Sulfito | C30: Diaria | D30: 30 - 60 mg/l
B31: Fosfato | C31: Diaria | D31: 30 - 60 mg/l
B32: TDS | C32: Diaria | D32: −
A34: Caldera N°2 | B34: Alcalinidad +M en CaCO3 | C34: Semanal | D34: ≤ 700 mg/l
B35: Alcalinidad OH¯ en CaCO3 | C35: Semanal | D35: ≥ 40 mg/l
B36: Conductividad | C36: Diaria | D36: 1.100 - 1.500 uS/cm
B37: pH | C37: Diaria | D37: 10,5 - 11,9
B38: Sílice en SiO2 | C38: Semanal | D38: ≤ 150 mg/l
B39: Dureza Total en CaCO3 | C39: Semanal | D39: ˂ 3 mg/l
B40: Hierro Total | C40: Mensual | D40: ˂ 1 mg/l
B41: Sulfito | C41: Diaria | D41: 30 - 60 mg/l
B42: Fosfato | C42: Diaria | D42: 30 - 60 mg/l
B43: TDS | C43: Diaria | D43: −
A45: Caldera N°3 | B45: Alcalinidad +M en CaCO3 | C45: Semanal | D45: ≤ 700 mg/l
B46: Alcalinidad OH¯ en CaCO3 | C46: Semanal | D46: ≥ 40 mg/l
B47: Conductividad | C47: Diaria | D47: 1.100 - 1.500 uS/cm
...

Sheet  16-03-26
C2: VARIABLE DE CONTROL SISTEMA DE GENERACIÓN DE VAPOR " PLANTA SALSAS Y UNTABLES" | H2: Codigo: FOXXX-0704-MAN
H3: Fecha actualización: XX/XX/XXXX
H4: Versión: X
A6: NOMBRE DE LA PLANTA: Alimentos Polar Comercial, C.A. Salsas y Untables
A7: DIRECCIÓN: Avenida Luis Ernesto Branger, Zona Industrial Norte II, Parroquia Rafael Urdaneta, Valencia, Edo. Carabobo,
A8: Venezuela. Código postal 2001.
A11: FECHA: | B11: 46097 | C11: Nombre y Apellido | E11: Eliezer D | F11: Angel M | G11: Observaciones
A12: Area | B12: Variable de control | D12: Rango Operación | E12: 1er Turno | F12: 2do Turno
E13: 0.29166667 | F13: 0.79166667
A14: Alimentación Calderas | B14: Hierro Total | C14: Semanal | D14: ≤ 0,1 mg/l
B15: Temperatura | C15: Diaria | D15: ≥ 104 °C
B16: Dureza Total en CaCO3 | C16: Diaria | D16: ≤ 0,3 mg/l
B17: Conductividad | C17: Semanal | D17: −
B18: pH | C18: Diaria | D18: 8,5 - 10,0
B19: Sílice en SiO2 | C19: Semanal | D19: −
B20: Alcalinidad +M en CaCO3 | C20: Semanal | D20: −
B21: Alcalinidad OH¯ en CaCO3 | C21: Semanal | D21: −
A23: Caldera N°1 | B23: Alcalinidad +M en CaCO3 | C23: Semanal | D23: ≤ 700 mg/l
B24: Alcalinidad OH¯ en CaCO3 | C24: Semanal | D24: ≥ 40 mg/l
B25: Conductividad | C25: Diaria | D25: 1.100 - 1.500 uS/cm
B26: pH | C26: Diaria | D26: 10,5 - 11,9
B27: Sílice en SiO2 | C27: Semanal | D27: ≤ 150 mg/l
B28: Dureza Total en CaCO3 | C28: Semanal | D28: ˂ 3 mg/l
B29: Hierro Total | C29: Mensual | D29: ˂ 1 mg/l
B30: Sulfito | C30: Diaria | D30: 30 - 60 mg/l
B31: Fosfato | C31: Diaria | D31: 30 - 60 mg/l
B32: TDS | C32: Diaria | D32: −
A34: Caldera N°2 | B34: Alcalinidad +M en CaCO3 | C34: Semanal | D34: ≤ 700 mg/l
B35: Alcalinidad OH¯ en CaCO3 | C35: Semanal | D35: ≥ 40 mg/l
B36: Conductividad | C36: Diaria | D36: 1.100 - 1.500 uS/cm
B37: pH | C37: Diaria | D37: 10,5 - 11,9
B38: Sílice en SiO2 | C38: Semanal | D38: ≤ 150 mg/l
B39: Dureza Total en CaCO3 | C39: Semanal | D39: ˂ 3 mg/l
B40: Hierro Total | C40: Mensual | D40: ˂ 1 mg/l
B41: Sulfito | C41: Diaria | D41: 30 - 60 mg/l
B42: Fosfato | C42: Diaria | D42: 30 - 60 mg/l
B43: TDS | C43: Diaria | D43: −
A45: Caldera N°3 | B45: Alcalinidad +M en CaCO3 | C45: Semanal | D45: ≤ 700 mg/l
B46: Alcalinidad OH¯ en CaCO3 | C46: Semanal | D46: ≥ 40 mg/l
B47: Conductividad | C47: Diaria | D47: 1.100 - 1.500 uS/cm
...

Sheet  17-03-26
C2: VARIABLE DE CONTROL SISTEMA DE GENERACIÓN DE VAPOR " PLANTA SALSAS Y UNTABLES" | H2: Codigo: FOXXX-0704-MAN
H3: Fecha actualización: XX/XX/XXXX
H4: Versión: X
A6: NOMBRE DE LA PLANTA: Alimentos Polar Comercial, C.A. Salsas y Untables
A7: DIRECCIÓN: Avenida Luis Ernesto Branger, Zona Industrial Norte II, Parroquia Rafael Urdaneta, Valencia, Edo. Carabobo,
A8: Venezuela. Código postal 2001.
A11: FECHA: | B11: 46098 | C11: Nombre y Apellido | E11: Eliezer D | F11: Angel M | G11: Observaciones
A12: Area | B12: Variable de control | D12: Rango Operación | E12: 1er Turno | F12: 2do Turno
E13: 0.29166667 | F13: 0.79166667
A14: Alimentación Calderas | B14: Hierro Total | C14: Semanal | D14: ≤ 0,1 mg/l
B15: Temperatura | C15: Diaria | D15: ≥ 104 °C | E15: 94.9 | F15: 93.6
B16: Dureza Total en CaCO3 | C16: Diaria | D16: ≤ 0,3 mg/l
B17: Conductividad | C17: Semanal | D17: −
B18: pH | C18: Diaria | D18: , | E18: 7.68 | F18: 7.77
B19: Sílice en SiO2 | C19: Semanal | D19: −
B20: Alcalinidad +M en CaCO3 | C20: Semanal | D20: −
B21: Alcalinidad OH¯ en CaCO3 | C21: Semanal | D21: −
A23: Caldera N°1 | B23: Alcalinidad +M en CaCO3 | C23: Semanal | D23: ≤ 700 mg/l
B24: Alcalinidad OH¯ en CaCO3 | C24: Semanal | D24: ≥ 40 mg/l
B25: Conductividad | C25: Diaria | D25: 1.100 - 1.500 uS/cm
B26: pH | C26: Diaria | D26: 10,5 - 11,9 | E26: 11.76 | F26: 11.7
B27: Sílice en SiO2 | C27: Semanal | D27: ≤ 150 mg/l
B28: Dureza Total en CaCO3 | C28: Semanal | D28: ˂ 3 mg/l
B29: Hierro Total | C29: Mensual | D29: ˂ 1 mg/l
B30: Sulfito | C30: Diaria | D30: 30 - 60 mg/l | E30: 44 | F30: 40
B31: Fosfato | C31: Diaria | D31: 30 - 60 mg/l | E31: 57.5 | F31: 42.5
B32: TDS | C32: Diaria | D32: −
A34: Caldera N°2 | B34: Alcalinidad +M en CaCO3 | C34: Semanal | D34: ≤ 700 mg/l
B35: Alcalinidad OH¯ en CaCO3 | C35: Semanal | D35: ≥ 40 mg/l
B36: Conductividad | C36: Diaria | D36: 1.100 - 1.500 uS/cm
B37: pH | C37: Diaria | D37: 10,5 - 11,9 | E37: 11.73 | F37: 11.77
B38: Sílice en SiO2 | C38: Semanal | D38: ≤ 150 mg/l
B39: Dureza Total en CaCO3 | C39: Semanal | D39: ˂ 3 mg/l
B40: Hierro Total | C40: Mensual | D40: ˂ 1 mg/l
B41: Sulfito | C41: Diaria | D41: 30 - 60 mg/l | E41: 32 | F41: 36
B42: Fosfato | C42: Diaria | D42: 30 - 60 mg/l | E42: 37.5 | F42: 40
B43: TDS | C43: Diaria | D43: −
A45: Caldera N°3 | B45: Alcalinidad +M en CaCO3 | C45: Semanal | D45: ≤ 700 mg/l
B46: Alcalinidad OH¯ en CaCO3 | C46: Semanal | D46: ≥ 40 mg/l
B47: Conductividad | C47: Diaria | D47: 1.100 - 1.500 uS/cm
...

Sheet  18-03-26
C2: VARIABLE DE CONTROL SISTEMA DE GENERACIÓN DE VAPOR " PLANTA SALSAS Y UNTABLES" | H2: Codigo: FOXXX-0704-MAN
H3: Fecha actualización: XX/XX/XXXX
H4: Versión: X
A6: NOMBRE DE LA PLANTA: Alimentos Polar Comercial, C.A. Salsas y Untables
A7: DIRECCIÓN: Avenida Luis Ernesto Branger, Zona Industrial Norte II, Parroquia Rafael Urdaneta, Valencia, Edo. Carabobo,
A8: Venezuela. Código postal 2001.
A11: FECHA: | B11: 46099 | C11: Nombre y Apellido | E11: Osman A | F11: Eliezer D | G11: Observaciones
A12: Area | B12: Variable de control | D12: Rango Operación | E12: 1er Turno | F12: 2do Turno
E13: 0.29166667 | F13: 0.79166667
A14: Alimentación Calderas | B14: Hierro Total | C14: Semanal | D14: ≤ 0,1 mg/l
B15: Temperatura | C15: Diaria | D15: ≥ 104 °C | E15: 95.8 | F15: 92.4
B16: Dureza Total en CaCO3 | C16: Diaria | D16: ≤ 0,3 mg/l
B17: Conductividad | C17: Semanal | D17: − | E17: 597
B18: pH | C18: Diaria | D18: 8,5 - 10,0 | E18: 7.91 | F18: 7.69
B19: Sílice en SiO2 | C19: Semanal | D19: −
B20: Alcalinidad +M en CaCO3 | C20: Semanal | D20: −
B21: Alcalinidad OH¯ en CaCO3 | C21: Semanal | D21: −
A23: Caldera N°1 | B23: Alcalinidad +M en CaCO3 | C23: Semanal | D23: ≤ 700 mg/l | E23: 1220
B24: Alcalinidad OH¯ en CaCO3 | C24: Semanal | D24: ≥ 40 mg/l | E24: 572
B25: Conductividad | C25: Diaria | D25: 1.100 - 1.500 uS/cm | E25: 3798 | F25: 3666
B26: pH | C26: Diaria | D26: 10,5 - 11,9 | E26: 11.82 | F26: 11.84
B27: Sílice en SiO2 | C27: Semanal | D27: ≤ 150 mg/l
B28: Dureza Total en CaCO3 | C28: Semanal | D28: ˂ 3 mg/l
B29: Hierro Total | C29: Mensual | D29: ˂ 1 mg/l
B30: Sulfito | C30: Diaria | D30: 30 - 60 mg/l | E30: 60 | F30: 45
B31: Fosfato | C31: Diaria | D31: 30 - 60 mg/l | E31: 57.5 | F31: 52.5
B32: TDS | C32: Diaria | D32: − | E32: 2865 | F32: 2736
A34: Caldera N°2 | B34: Alcalinidad +M en CaCO3 | C34: Semanal | D34: ≤ 700 mg/l | E34: 1028
B35: Alcalinidad OH¯ en CaCO3 | C35: Semanal | D35: ≥ 40 mg/l | E35: 572
B36: Conductividad | C36: Diaria | D36: 1.100 - 1.500 uS/cm | E36: 3510 | F36: 2359
B37: pH | C37: Diaria | D37: 10,5 - 11,9 | E37: 11.7 | F37: 11.64
B38: Sílice en SiO2 | C38: Semanal | D38: ≤ 150 mg/l
B39: Dureza Total en CaCO3 | C39: Semanal | D39: ˂ 3 mg/l
B40: Hierro Total | C40: Mensual | D40: ˂ 1 mg/l
B41: Sulfito | C41: Diaria | D41: 30 - 60 mg/l | E41: 58 | F41: 25
B42: Fosfato | C42: Diaria | D42: 30 - 60 mg/l | E42: 60 | F42: 38
B43: TDS | C43: Diaria | D43: − | E43: 2630 | F43: 1708
A45: Caldera N°3 | B45: Alcalinidad +M en CaCO3 | C45: Semanal | D45: ≤ 700 mg/l | E45: 836
B46: Alcalinidad OH¯ en CaCO3 | C46: Semanal | D46: ≥ 40 mg/l | E46: 364
B47: Conductividad | C47: Diaria | D47: 1.100 - 1.500 uS/cm | E47: 2670 | F47: 2651
...

Sheet  19-03-26
C2: VARIABLE DE CONTROL SISTEMA DE GENERACIÓN DE VAPOR " PLANTA SALSAS Y UNTABLES" | H2: Codigo: FOXXX-0704-MAN
H3: Fecha actualización: XX/XX/XXXX
H4: Versión: X
A6: NOMBRE DE LA PLANTA: Alimentos Polar Comercial, C.A. Salsas y Untables
A7: DIRECCIÓN: Avenida Luis Ernesto Branger, Zona Industrial Norte II, Parroquia Rafael Urdaneta, Valencia, Edo. Carabobo,
A8: Venezuela. Código postal 2001.
A11: FECHA: | B11: 46100 | C11: Nombre y Apellido | E11: Osman A | F11: Eliezer D | G11: Observaciones
A12: Area | B12: Variable de control | D12: Rango Operación | E12: 1er Turno | F12: 2do Turno
E13: 0.29166667 | F13: 0.79166667
A14: Alimentación Calderas | B14: Hierro Total | C14: Semanal | D14: ≤ 0,1 mg/l
B15: Temperatura | C15: Diaria | D15: ≥ 104 °C | E15: 93 | F15: 92.3
B16: Dureza Total en CaCO3 | C16: Diaria | D16: ≤ 0,3 mg/l
B17: Conductividad | C17: Semanal | D17: − | E17: 604
B18: pH | C18: Diaria | D18: 8,5 - 10,0 | E18: 7.73 | F18: 7.68
B19: Sílice en SiO2 | C19: Semanal | D19: −
B20: Alcalinidad +M en CaCO3 | C20: Semanal | D20: −
B21: Alcalinidad OH¯ en CaCO3 | C21: Semanal | D21: −
A23: Caldera N°1 | B23: Alcalinidad +M en CaCO3 | C23: Semanal | D23: ≤ 700 mg/l
B24: Alcalinidad OH¯ en CaCO3 | C24: Semanal | D24: ≥ 40 mg/l
B25: Conductividad | C25: Diaria | D25: 1.100 - 1.500 uS/cm | E25: 3451 | F25: 3617
B26: pH | C26: Diaria | D26: 10,5 - 11,9 | E26: 11.86 | F26: 11.87
B27: Sílice en SiO2 | C27: Semanal | D27: ≤ 150 mg/l
B28: Dureza Total en CaCO3 | C28: Semanal | D28: ˂ 3 mg/l
B29: Hierro Total | C29: Mensual | D29: ˂ 1 mg/l
B30: Sulfito | C30: Diaria | D30: 30 - 60 mg/l | E30: 38 | F30: 54
B31: Fosfato | C31: Diaria | D31: 30 - 60 mg/l | E31: 60 | F31: 45
B32: TDS | C32: Diaria | D32: − | E32: 2583 | F32: 2762
A34: Caldera N°2 | B34: Alcalinidad +M en CaCO3 | C34: Semanal | D34: ≤ 700 mg/l
B35: Alcalinidad OH¯ en CaCO3 | C35: Semanal | D35: ≥ 40 mg/l
B36: Conductividad | C36: Diaria | D36: 1.100 - 1.500 uS/cm | E36: 3285 | F36: 3435
B37: pH | C37: Diaria | D37: 10,5 - 11,9 | E37: 11.9 | F37: 11.85
B38: Sílice en SiO2 | C38: Semanal | D38: ≤ 150 mg/l
B39: Dureza Total en CaCO3 | C39: Semanal | D39: ˂ 3 mg/l
B40: Hierro Total | C40: Mensual | D40: ˂ 1 mg/l
B41: Sulfito | C41: Diaria | D41: 30 - 60 mg/l | E41: 30 | F41: 32
B42: Fosfato | C42: Diaria | D42: 30 - 60 mg/l | E42: 37.5 | F42: 35
B43: TDS | C43: Diaria | D43: − | E43: 2450 | F43: 2555
A45: Caldera N°3 | B45: Alcalinidad +M en CaCO3 | C45: Semanal | D45: ≤ 700 mg/l
B46: Alcalinidad OH¯ en CaCO3 | C46: Semanal | D46: ≥ 40 mg/l
B47: Conductividad | C47: Diaria | D47: 1.100 - 1.500 uS/cm | E47: 1656 | F47: 2284
...

Sheet  20-03-26
C2: VARIABLE DE CONTROL SISTEMA DE GENERACIÓN DE VAPOR " PLANTA SALSAS Y UNTABLES" | H2: Codigo: FOXXX-0704-MAN
H3: Fecha actualización: XX/XX/XXXX
H4: Versión: X
A6: NOMBRE DE LA PLANTA: Alimentos Polar Comercial, C.A. Salsas y Untables
A7: DIRECCIÓN: Avenida Luis Ernesto Branger, Zona Industrial Norte II, Parroquia Rafael Urdaneta, Valencia, Edo. Carabobo,
A8: Venezuela. Código postal 2001.
A11: FECHA: | B11: 46101 | C11: Nombre y Apellido | E11: Arturo C | F11: Osman A | G11: Observaciones
A12: Area | B12: Variable de control | D12: Rango Operación | E12: 1er Turno | F12: 2do Turno
E13: 0.29166667 | F13: 0.79166667
A14: Alimentación Calderas | B14: Hierro Total | C14: Semanal | D14: ≤ 0,1 mg/l
B15: Temperatura | C15: Diaria | D15: ≥ 104 °C | E15: 92.7 | F15: 92.4
B16: Dureza Total en CaCO3 | C16: Diaria | D16: ≤ 0,3 mg/l
B17: Conductividad | C17: Semanal | D17: − | E17: 586 | F17: 597
B18: pH | C18: Diaria | D18: 8,5 - 10,0 | E18: 7.82 | F18: 7.72
B19: Sílice en SiO2 | C19: Semanal | D19: −
B20: Alcalinidad +M en CaCO3 | C20: Semanal | D20: −
B21: Alcalinidad OH¯ en CaCO3 | C21: Semanal | D21: −
A23: Caldera N°1 | B23: Alcalinidad +M en CaCO3 | C23: Semanal | D23: ≤ 700 mg/l
B24: Alcalinidad OH¯ en CaCO3 | C24: Semanal | D24: ≥ 40 mg/l
B25: Conductividad | C25: Diaria | D25: 1.100 - 1.500 uS/cm | E25: 3144 | F25: 3188
B26: pH | C26: Diaria | D26: 10,5 - 11,9 | E26: 11.65 | F26: 11.73
B27: Sílice en SiO2 | C27: Semanal | D27: ≤ 150 mg/l
B28: Dureza Total en CaCO3 | C28: Semanal | D28: ˂ 3 mg/l
B29: Hierro Total | C29: Mensual | D29: ˂ 1 mg/l
B30: Sulfito | C30: Diaria | D30: 30 - 60 mg/l | E30: 36 | F30: 32
B31: Fosfato | C31: Diaria | D31: 30 - 60 mg/l | E31: 30 | F31: 45
B32: TDS | C32: Diaria | D32: − | E32: 2360 | F32: 2362
A34: Caldera N°2 | B34: Alcalinidad +M en CaCO3 | C34: Semanal | D34: ≤ 700 mg/l
B35: Alcalinidad OH¯ en CaCO3 | C35: Semanal | D35: ≥ 40 mg/l
B36: Conductividad | C36: Diaria | D36: 1.100 - 1.500 uS/cm | E36: 3365 | F36: 3260
B37: pH | C37: Diaria | D37: 10,5 - 11,9 | E37: 11.72 | F37: 11.84
B38: Sílice en SiO2 | C38: Semanal | D38: ≤ 150 mg/l
B39: Dureza Total en CaCO3 | C39: Semanal | D39: ˂ 3 mg/l
B40: Hierro Total | C40: Mensual | D40: ˂ 1 mg/l
B41: Sulfito | C41: Diaria | D41: 30 - 60 mg/l | E41: 38 | F41: 34
B42: Fosfato | C42: Diaria | D42: 30 - 60 mg/l | E42: 27.5 | F42: 50
B43: TDS | C43: Diaria | D43: − | E43: 2489 | F43: 2423
A45: Caldera N°3 | B45: Alcalinidad +M en CaCO3 | C45: Semanal | D45: ≤ 700 mg/l
B46: Alcalinidad OH¯ en CaCO3 | C46: Semanal | D46: ≥ 40 mg/l
B47: Conductividad | C47: Diaria | D47: 1.100 - 1.500 uS/cm | E47: 2073 | F47: 2016
...

Sheet  21-03-26
C2: VARIABLE DE CONTROL SISTEMA DE GENERACIÓN DE VAPOR " PLANTA SALSAS Y UNTABLES" | H2: Codigo: FOXXX-0704-MAN
H3: Fecha actualización: XX/XX/XXXX
H4: Versión: X
A6: NOMBRE DE LA PLANTA: Alimentos Polar Comercial, C.A. Salsas y Untables
A7: DIRECCIÓN: Avenida Luis Ernesto Branger, Zona Industrial Norte II, Parroquia Rafael Urdaneta, Valencia, Edo. Carabobo,
A8: Venezuela. Código postal 2001.
A11: FECHA: | B11: 46102 | C11: Nombre y Apellido | E11: Arturo C | F11: Osman A | G11: Observaciones
A12: Area | B12: Variable de control | D12: Rango Operación | E12: 1er Turno | F12: 2do Turno
E13: 0.29166667 | F13: 0.79166667
A14: Alimentación Calderas | B14: Hierro Total | C14: Semanal | D14: ≤ 0,1 mg/l
B15: Temperatura | C15: Diaria | D15: ≥ 104 °C | E15: 92.9 | F15: 92.6
B16: Dureza Total en CaCO3 | C16: Diaria | D16: ≤ 0,3 mg/l
B17: Conductividad | C17: Semanal | D17: − | E17: 617 | F17: 623
B18: pH | C18: Diaria | D18: 8,5 - 10,0 | E18: 7.59 | F18: 7.64
B19: Sílice en SiO2 | C19: Semanal | D19: −
B20: Alcalinidad +M en CaCO3 | C20: Semanal | D20: −
B21: Alcalinidad OH¯ en CaCO3 | C21: Semanal | D21: −
A23: Caldera N°1 | B23: Alcalinidad +M en CaCO3 | C23: Semanal | D23: ≤ 700 mg/l
B24: Alcalinidad OH¯ en CaCO3 | C24: Semanal | D24: ≥ 40 mg/l
B25: Conductividad | C25: Diaria | D25: 1.100 - 1.500 uS/cm | E25: 2638 | F25: 2858
B26: pH | C26: Diaria | D26: 10,5 - 11,9 | E26: 11.23 | F26: 11.64
B27: Sílice en SiO2 | C27: Semanal | D27: ≤ 150 mg/l
B28: Dureza Total en CaCO3 | C28: Semanal | D28: ˂ 3 mg/l
B29: Hierro Total | C29: Mensual | D29: ˂ 1 mg/l
B30: Sulfito | C30: Diaria | D30: 30 - 60 mg/l | E30: 65 | F30: 58
B31: Fosfato | C31: Diaria | D31: 30 - 60 mg/l | E31: 47.5 | F31: 57.5
B32: TDS | C32: Diaria | D32: − | E32: 1931 | F32: 2113
A34: Caldera N°2 | B34: Alcalinidad +M en CaCO3 | C34: Semanal | D34: ≤ 700 mg/l
B35: Alcalinidad OH¯ en CaCO3 | C35: Semanal | D35: ≥ 40 mg/l
B36: Conductividad | C36: Diaria | D36: 1.100 - 1.500 uS/cm | E36: 3299 | F36: 3062
B37: pH | C37: Diaria | D37: 10,5 - 11,9 | E37: 11.5 | F37: 11.67
B38: Sílice en SiO2 | C38: Semanal | D38: ≤ 150 mg/l
B39: Dureza Total en CaCO3 | C39: Semanal | D39: ˂ 3 mg/l
B40: Hierro Total | C40: Mensual | D40: ˂ 1 mg/l
B41: Sulfito | C41: Diaria | D41: 30 - 60 mg/l | E41: 66 | F41: 56
B42: Fosfato | C42: Diaria | D42: 30 - 60 mg/l | E42: 40 | F42: 35
B43: TDS | C43: Diaria | D43: − | E43: 2436 | F43: 2238
A45: Caldera N°3 | B45: Alcalinidad +M en CaCO3 | C45: Semanal | D45: ≤ 700 mg/l
B46: Alcalinidad OH¯ en CaCO3 | C46: Semanal | D46: ≥ 40 mg/l
B47: Conductividad | C47: Diaria | D47: 1.100 - 1.500 uS/cm | E47: 2495 | F47: 1623
...

Sheet  22-03-26
C2: VARIABLE DE CONTROL SISTEMA DE GENERACIÓN DE VAPOR " PLANTA SALSAS Y UNTABLES" | H2: Codigo: FOXXX-0704-MAN
H3: Fecha actualización: XX/XX/XXXX
H4: Versión: X
A6: NOMBRE DE LA PLANTA: Alimentos Polar Comercial, C.A. Salsas y Untables
A7: DIRECCIÓN: Avenida Luis Ernesto Branger, Zona Industrial Norte II, Parroquia Rafael Urdaneta, Valencia, Edo. Carabobo,
A8: Venezuela. Código postal 2001.
A11: FECHA: | B11: 46103 | C11: Nombre y Apellido | E11: Angel M | F11: Yan C | G11: Observaciones
A12: Area | B12: Variable de control | D12: Rango Operación | E12: 1er Turno | F12: 2do Turno
E13: 0.29166667 | F13: 0.79166667
A14: Alimentación Calderas | B14: Hierro Total | C14: Semanal | D14: ≤ 0,1 mg/l
B15: Temperatura | C15: Diaria | D15: ≥ 104 °C | E15: 93.6 | F15: 92.8
B16: Dureza Total en CaCO3 | C16: Diaria | D16: ≤ 0,3 mg/l
B17: Conductividad | C17: Semanal | D17: − | F17: 583
B18: pH | C18: Diaria | D18: 8,5 - 10,0 | E18: 7.62 | F18: 7.68
B19: Sílice en SiO2 | C19: Semanal | D19: −
B20: Alcalinidad +M en CaCO3 | C20: Semanal | D20: −
B21: Alcalinidad OH¯ en CaCO3 | C21: Semanal | D21: −
A23: Caldera N°1 | B23: Alcalinidad +M en CaCO3 | C23: Semanal | D23: ≤ 700 mg/l
B24: Alcalinidad OH¯ en CaCO3 | C24: Semanal | D24: ≥ 40 mg/l
B25: Conductividad | C25: Diaria | D25: 1.100 - 1.500 uS/cm | E25: 3008 | F25: 3141
B26: pH | C26: Diaria | D26: 10,5 - 11,9 | E26: 11.45 | F26: 11.76
B27: Sílice en SiO2 | C27: Semanal | D27: ≤ 150 mg/l
B28: Dureza Total en CaCO3 | C28: Semanal | D28: ˂ 3 mg/l
B29: Hierro Total | C29: Mensual | D29: ˂ 1 mg/l
B30: Sulfito | C30: Diaria | D30: 30 - 60 mg/l | E30: 80 | F30: 78
B31: Fosfato | C31: Diaria | D31: 30 - 60 mg/l | E31: 52.5 | F31: 37.5
B32: TDS | C32: Diaria | D32: − | E32: 2181 | F32: 2320
A34: Caldera N°2 | B34: Alcalinidad +M en CaCO3 | C34: Semanal | D34: ≤ 700 mg/l
B35: Alcalinidad OH¯ en CaCO3 | C35: Semanal | D35: ≥ 40 mg/l
B36: Conductividad | C36: Diaria | D36: 1.100 - 1.500 uS/cm | E36: 2054 | F36: 1301
B37: pH | C37: Diaria | D37: 10,5 - 11,9 | E37: 10.9 | F37: 10.61
B38: Sílice en SiO2 | C38: Semanal | D38: ≤ 150 mg/l
B39: Dureza Total en CaCO3 | C39: Semanal | D39: ˂ 3 mg/l
B40: Hierro Total | C40: Mensual | D40: ˂ 1 mg/l
B41: Sulfito | C41: Diaria | D41: 30 - 60 mg/l | E41: 20 | F41: 26
B42: Fosfato | C42: Diaria | D42: 30 - 60 mg/l | E42: 40 | F42: 30
B43: TDS | C43: Diaria | D43: − | E43: 1917 | F43: 905
A45: Caldera N°3 | B45: Alcalinidad +M en CaCO3 | C45: Semanal | D45: ≤ 700 mg/l
B46: Alcalinidad OH¯ en CaCO3 | C46: Semanal | D46: ≥ 40 mg/l
B47: Conductividad | C47: Diaria | D47: 1.100 - 1.500 uS/cm | E47: 2248 | F47: 2158
...

Sheet  23-03-26
C2: VARIABLE DE CONTROL SISTEMA DE GENERACIÓN DE VAPOR " PLANTA SALSAS Y UNTABLES" | H2: Codigo: FOXXX-0704-MAN
H3: Fecha actualización: XX/XX/XXXX
H4: Versión: X
A6: NOMBRE DE LA PLANTA: Alimentos Polar Comercial, C.A. Salsas y Untables
A7: DIRECCIÓN: Avenida Luis Ernesto Branger, Zona Industrial Norte II, Parroquia Rafael Urdaneta, Valencia, Edo. Carabobo,
A8: Venezuela. Código postal 2001.
A11: FECHA: | B11: 46104 | C11: Nombre y Apellido | E11: Angel M | F11: Yan C | G11: Observaciones
A12: Area | B12: Variable de control | D12: Rango Operación | E12: 1er Turno | F12: 2do Turno
E13: 0.29166667 | F13: 0.79166667
A14: Alimentación Calderas | B14: Hierro Total | C14: Semanal | D14: ≤ 0,1 mg/l
B15: Temperatura | C15: Diaria | D15: ≥ 104 °C | E15: 90.9 | F15: 93.9
B16: Dureza Total en CaCO3 | C16: Diaria | D16: ≤ 0,3 mg/l | F16: 0
B17: Conductividad | C17: Semanal | D17: − | F17: 607
B18: pH | C18: Diaria | D18: 8,5 - 10,0 | E18: 7.67 | F18: 7.7
B19: Sílice en SiO2 | C19: Semanal | D19: −
B20: Alcalinidad +M en CaCO3 | C20: Semanal | D20: −
B21: Alcalinidad OH¯ en CaCO3 | C21: Semanal | D21: −
A23: Caldera N°1 | B23: Alcalinidad +M en CaCO3 | C23: Semanal | D23: ≤ 700 mg/l
B24: Alcalinidad OH¯ en CaCO3 | C24: Semanal | D24: ≥ 40 mg/l
B25: Conductividad | C25: Diaria | D25: 1.100 - 1.500 uS/cm | F25: 3583
B26: pH | C26: Diaria | D26: 10,5 - 11,9 | E26: 11.72 | F26: 11.73
B27: Sílice en SiO2 | C27: Semanal | D27: ≤ 150 mg/l
B28: Dureza Total en CaCO3 | C28: Semanal | D28: ˂ 3 mg/l
B29: Hierro Total | C29: Mensual | D29: ˂ 1 mg/l
B30: Sulfito | C30: Diaria | D30: 30 - 60 mg/l | E30: 66 | F30: 68
B31: Fosfato | C31: Diaria | D31: 30 - 60 mg/l | E31: 35 | F31: 37.5
B32: TDS | C32: Diaria | D32: − | E32: 2421 | F32: 2663
A34: Caldera N°2 | B34: Alcalinidad +M en CaCO3 | C34: Semanal | D34: ≤ 700 mg/l
B35: Alcalinidad OH¯ en CaCO3 | C35: Semanal | D35: ≥ 40 mg/l
B36: Conductividad | C36: Diaria | D36: 1.100 - 1.500 uS/cm | F36: 1060
B37: pH | C37: Diaria | D37: 10,5 - 11,9 | E37: 10.7 | F37: 10.9
B38: Sílice en SiO2 | C38: Semanal | D38: ≤ 150 mg/l
B39: Dureza Total en CaCO3 | C39: Semanal | D39: ˂ 3 mg/l
B40: Hierro Total | C40: Mensual | D40: ˂ 1 mg/l
B41: Sulfito | C41: Diaria | D41: 30 - 60 mg/l | E41: 30 | F41: 31
B42: Fosfato | C42: Diaria | D42: 30 - 60 mg/l | E42: 32.5 | F42: 27.5
B43: TDS | C43: Diaria | D43: − | E43: 1210 | F43: 722
A45: Caldera N°3 | B45: Alcalinidad +M en CaCO3 | C45: Semanal | D45: ≤ 700 mg/l
B46: Alcalinidad OH¯ en CaCO3 | C46: Semanal | D46: ≥ 40 mg/l
B47: Conductividad | C47: Diaria | D47: 1.100 - 1.500 uS/cm | F47: 2268
...

Sheet  24-03-26
C2: VARIABLE DE CONTROL SISTEMA DE GENERACIÓN DE VAPOR " PLANTA SALSAS Y UNTABLES" | H2: Codigo: FOXXX-0704-MAN
H3: Fecha actualización: XX/XX/XXXX
H4: Versión: X
A6: NOMBRE DE LA PLANTA: Alimentos Polar Comercial, C.A. Salsas y Untables
A7: DIRECCIÓN: Avenida Luis Ernesto Branger, Zona Industrial Norte II, Parroquia Rafael Urdaneta, Valencia, Edo. Carabobo,
A8: Venezuela. Código postal 2001.
A11: FECHA: | B11: 46105 | C11: Nombre y Apellido | E11: Juan M | F11: Angel M | G11: Observaciones
A12: Area | B12: Variable de control | D12: Rango Operación | E12: 1er Turno | F12: 2do Turno
E13: 0.29166667 | F13: 0.79166667
